<?xml version="1.0" ?>
<robot name="amr" xmlns:xacro="http://www.ros.org/wiki/xacro">

<xacro:include filename="$(find amr_description)/urdf/materials.xacro" />
<xacro:include filename="$(find amr_description)/urdf/amr.trans" />
<xacro:include filename="$(find amr_description)/urdf/amr.gazebo" />
<link name="base_link">
  <inertial>
    <origin xyz="-0.10140304112172575 -0.07 0.06559338049633992" rpy="0 0 0"/>
    <mass value="3.972072439042729"/>
    <inertia ixx="0.014301" iyy="0.031378" izz="0.042871" ixy="0.0" iyz="0.0" ixz="-0.000459"/>
  </inertial>
  <visual>
    <origin xyz="0 0 0" rpy="0 0 0"/>
    <geometry>
      <mesh filename="package://amr_description/meshes/base_link.stl" scale="0.001 0.001 0.001"/>
    </geometry>
    <material name="silver"/>
  </visual>
  <collision>
    <origin xyz="0 0 0" rpy="0 0 0"/>
    <geometry>
      <mesh filename="package://amr_description/meshes/base_link.stl" scale="0.001 0.001 0.001"/>
    </geometry>
  </collision>
</link>

<link name="left_wheel_f_1">
  <inertial>
    <origin xyz="4.983650736169881e-07 0.010000000000000016 1.4282942839560775e-07" rpy="0 0 0"/>
    <mass value="0.24157045638565464"/>
    <inertia ixx="0.000258" iyy="0.000499" izz="0.000258" ixy="0.0" iyz="0.0" ixz="0.0"/>
  </inertial>
  <visual>
    <origin xyz="0.012881 -0.038 -0.064297" rpy="0 0 0"/>
    <geometry>
      <mesh filename="package://amr_description/meshes/left_wheel_f_1.stl" scale="0.001 0.001 0.001"/>
    </geometry>
    <material name="silver"/>
  </visual>
  <collision>
    <origin xyz="0.012881 -0.038 -0.064297" rpy="0 0 0"/>
    <geometry>
      <mesh filename="package://amr_description/meshes/left_wheel_f_1.stl" scale="0.001 0.001 0.001"/>
    </geometry>
  </collision>
</link>

<link name="left_wheel_b_1">
  <inertial>
    <origin xyz="-1.7951529185378234e-07 0.010000000000000044 1.4282942842336332e-07" rpy="0 0 0"/>
    <mass value="0.2415704563856548"/>
    <inertia ixx="0.000258" iyy="0.000499" izz="0.000258" ixy="0.0" iyz="0.0" ixz="0.0"/>
  </inertial>
  <visual>
    <origin xyz="0.204556 -0.038 -0.064297" rpy="0 0 0"/>
    <geometry>
      <mesh filename="package://amr_description/meshes/left_wheel_b_1.stl" scale="0.001 0.001 0.001"/>
    </geometry>
    <material name="silver"/>
  </visual>
  <collision>
    <origin xyz="0.204556 -0.038 -0.064297" rpy="0 0 0"/>
    <geometry>
      <mesh filename="package://amr_description/meshes/left_wheel_b_1.stl" scale="0.001 0.001 0.001"/>
    </geometry>
  </collision>
</link>

<link name="right_wheel_f_1">
  <inertial>
    <origin xyz="4.983650735458645e-07 -0.010000000000000064 1.4282942835397439e-07" rpy="0 0 0"/>
    <mass value="0.24157045638565475"/>
    <inertia ixx="0.000258" iyy="0.000499" izz="0.000258" ixy="0.0" iyz="-0.0" ixz="-0.0"/>
  </inertial>
  <visual>
    <origin xyz="0.012881 0.178 -0.064297" rpy="0 0 0"/>
    <geometry>
      <mesh filename="package://amr_description/meshes/right_wheel_f_1.stl" scale="0.001 0.001 0.001"/>
    </geometry>
    <material name="silver"/>
  </visual>
  <collision>
    <origin xyz="0.012881 0.178 -0.064297" rpy="0 0 0"/>
    <geometry>
      <mesh filename="package://amr_description/meshes/right_wheel_f_1.stl" scale="0.001 0.001 0.001"/>
    </geometry>
  </collision>
</link>

<link name="right_wheel_b_1">
  <inertial>
    <origin xyz="-1.7951529188153792e-07 -0.009999999999999953 1.4282942838172996e-07" rpy="0 0 0"/>
    <mass value="0.24157045638565475"/>
    <inertia ixx="0.000258" iyy="0.000499" izz="0.000258" ixy="-0.0" iyz="0.0" ixz="-0.0"/>
  </inertial>
  <visual>
    <origin xyz="0.204556 0.178 -0.064297" rpy="0 0 0"/>
    <geometry>
      <mesh filename="package://amr_description/meshes/right_wheel_b_1.stl" scale="0.001 0.001 0.001"/>
    </geometry>
    <material name="silver"/>
  </visual>
  <collision>
    <origin xyz="0.204556 0.178 -0.064297" rpy="0 0 0"/>
    <geometry>
      <mesh filename="package://amr_description/meshes/right_wheel_b_1.stl" scale="0.001 0.001 0.001"/>
    </geometry>
  </collision>
</link>

<link name="lidar_1">
  <inertial>
    <origin xyz="-3.3028358275427605e-07 0.0 0.015000142829428367" rpy="0 0 0"/>
    <mass value="0.12238074182059036"/>
    <inertia ixx="4.7e-05" iyy="4.7e-05" izz="7.5e-05" ixy="-0.0" iyz="0.0" ixz="-0.0"/>
  </inertial>
  <visual>
    <origin xyz="0.012166 0.07 -0.121297" rpy="0 0 0"/>
    <geometry>
      <mesh filename="package://amr_description/meshes/lidar_1.stl" scale="0.001 0.001 0.001"/>
    </geometry>
    <material name="silver"/>
  </visual>
  <collision>
    <origin xyz="0.012166 0.07 -0.121297" rpy="0 0 0"/>
    <geometry>
      <mesh filename="package://amr_description/meshes/lidar_1.stl" scale="0.001 0.001 0.001"/>
    </geometry>
  </collision>
</link>

<joint name="Rev1" type="continuous">
  <origin xyz="-0.012881 0.038 0.064297" rpy="0 0 0"/>
  <parent link="base_link"/>
  <child link="left_wheel_f_1"/>
  <axis xyz="0.0 1.0 0.0"/>
</joint>

<joint name="Rev2" type="continuous">
  <origin xyz="-0.204556 0.038 0.064297" rpy="0 0 0"/>
  <parent link="base_link"/>
  <child link="left_wheel_b_1"/>
  <axis xyz="0.0 1.0 0.0"/>
</joint>

<joint name="Rev3" type="continuous">
  <origin xyz="-0.012881 -0.178 0.064297" rpy="0 0 0"/>
  <parent link="base_link"/>
  <child link="right_wheel_f_1"/>
  <axis xyz="-0.0 -1.0 0.0"/>
</joint>

<joint name="Rev4" type="continuous">
  <origin xyz="-0.204556 -0.178 0.064297" rpy="0 0 0"/>
  <parent link="base_link"/>
  <child link="right_wheel_b_1"/>
  <axis xyz="-0.0 1.0 0.0"/>
</joint>

<joint name="Rigid5" type="fixed">
  <origin xyz="-0.012166 -0.07 0.121297" rpy="0 0 0"/>
  <parent link="base_link"/>
  <child link="lidar_1"/>
</joint>

</robot>
